Workbook

Sheet flattenedfeatures
A1: SID | B1: ="ABS_"&DC1 -> ABS_Attention_LDLPFC-Attention_RDLPFC | C1: ="ABS_"&DD1 -> ABS_Attention_LDLPFC-Attention_LIPL | D1: ="ABS_"&DE1 -> ABS_Attention_RDLPFC-Attention_LIPL | E1: ="ABS_"&DF1 -> ABS_Attention_LDLPFC-Attention_RIPL | F1: ="ABS_"&DG1 -> ABS_Attention_RDLPFC-Attention_RIPL | G1: ="ABS_"&DH1 -> ABS_Attention_LIPL-Attention_RIPL | H1: ="ABS_"&DI1 -> ABS_Attention_LDLPFC-Attention_mSPFC | I1: ="ABS_"&DJ1 -> ABS_Attention_RDLPFC-Attention_mSPFC | ... DB1: ="ABS_"&HC1 -> ABS_Salience_LAmygdala-Salience_RAmygdala | DC1: Attention_LDLPFC-Attention_RDLPFC | DD1: Attention_LDLPFC-Attention_LIPL | DE1: Attention_RDLPFC-Attention_LIPL | DF1: Attention_LDLPFC-Attention_RIPL | DG1: Attention_RDLPFC-Attention_RIPL | DH1: Attention_LIPL-Attention_RIPL | DI1: Attention_LDLPFC-Attention_mSPFC | DJ1: Attention_RDLPFC-Attention_mSPFC | DK1: Attention_LIPL-Attention_mSPFC | DL1: Attention_RIPL-Attention_mSPFC | DM1: Attention_LDLPFC-Attention_LPrecuneus | DN1: Attention_RDLPFC-Attention_LPrecuneus | DO1: Attention_LIPL-Attention_LPrecuneus | DP1: Attention_RIPL-Attention_LPrecuneus | DQ1: Attention_mSPFC-Attention_LPrecuneus | DR1: Attention_LDLPFC-Attention_RPrecuneus | DS1: Attention_RDLPFC-Attention_RPrecuneus | DT1: Attention_LIPL-Attention_RPrecuneus | DU1: Attention_RIPL-Attention_RPrecuneus | DV1: Attention_mSPFC-Attention_RPrecuneus | DW1: Attention_LPrecuneus-Attention_RPrecuneus | DX1: Attention_LDLPFC-DMN_LAngularGyrus | DY1: Attention_RDLPFC-DMN_LAngularGyrus | DZ1: Attention_LIPL-DMN_LAngularGyrus | EA1: Attention_RIPL-DMN_LAngularGyrus | EB1: Attention_mSPFC-DMN_LAngularGyrus | EC1: Attention_LPrecuneus-DMN_LAngularGyrus | ED1: Attention_RPrecuneus-DMN_LAngularGyrus | EE1: Attention_LDLPFC-DMN_RAngularGyrus | EF1: Attention_RDLPFC-DMN_RAngularGyrus | EG1: Attention_LIPL-DMN_RAngularGyrus | EH1: Attention_RIPL-DMN_RAngularGyrus | EI1: Attention_mSPFC-DMN_RAngularGyrus | EJ1: Attention_LPrecuneus-DMN_RAngularGyrus | EK1: Attention_RPrecuneus-DMN_RAngularGyrus | EL1: DMN_LAngularGyrus-DMN_RAngularGyrus | EM1: Attention_LDLPFC-DMN_PCC | EN1: Attention_RDLPFC-DMN_PCC | EO1: Attention_LIPL-DMN_PCC | EP1: Attention_RIPL-DMN_PCC | EQ1: Attention_mSPFC-DMN_PCC | ER1: Attention_LPrecuneus-DMN_PCC | ES1: Attention_RPrecuneus-DMN_PCC | ET1: DMN_LAngularGyrus-DMN_PCC | EU1: DMN_RAngularGyrus-DMN_PCC | EV1: Attention_LDLPFC-DMN_MPFC | EW1: Attention_RDLPFC-DMN_MPFC | EX1: Attention_LIPL-DMN_MPFC | EY1: Attention_RIPL-DMN_MPFC | EZ1: Attention_mSPFC-DMN_MPFC | FA1: Attention_LPrecuneus-DMN_MPFC | FB1: Attention_RPrecuneus-DMN_MPFC | FC1: DMN_LAngularGyrus-DMN_MPFC | FD1: DMN_RAngularGyrus-DMN_MPFC | FE1: DMN_PCC-DMN_MPFC | FF1: Attention_LDLPFC-Salience_LInsula | FG1: Attention_RDLPFC-Salience_LInsula | FH1: Attention_LIPL-Salience_LInsula | FI1: Attention_RIPL-Salience_LInsula | FJ1: Attention_mSPFC-Salience_LInsula | FK1: Attention_LPrecuneus-Salience_LInsula | FL1: Attention_RPrecuneus-Salience_LInsula | FM1: DMN_LAngularGyrus-Salience_LInsula | FN1: DMN_RAngularGyrus-Salience_LInsula | FO1: DMN_PCC-Salience_LInsula | FP1: DMN_MPFC-Salience_LInsula | FQ1: Attention_LDLPFC-Salience_RInsula | FR1: Attention_RDLPFC-Salience_RInsula | FS1: Attention_LIPL-Salience_RInsula | FT1: Attention_RIPL-Salience_RInsula | FU1: Attention_mSPFC-Salience_RInsula | FV1: Attention_LPrecuneus-Salience_RInsula | FW1: Attention_RPrecuneus-Salience_RInsula | FX1: DMN_LAngularGyrus-Salience_RInsula | FY1: DMN_RAngularGyrus-Salience_RInsula | FZ1: DMN_PCC-Salience_RInsula | GA1: DMN_MPFC-Salience_RInsula | GB1: Salience_LInsula-Salience_RInsula | GC1: Attention_LDLPFC-Salience_LAmygdala | GD1: Attention_RDLPFC-Salience_LAmygdala | GE1: Attention_LIPL-Salience_LAmygdala | GF1: Attention_RIPL-Salience_LAmygdala | GG1: Attention_mSPFC-Salience_LAmygdala | GH1: Attention_LPrecuneus-Salience_LAmygdala | GI1: Attention_RPrecuneus-Salience_LAmygdala | GJ1: DMN_LAngularGyrus-Salience_LAmygdala | GK1: DMN_RAngularGyrus-Salience_LAmygdala | GL1: DMN_PCC-Salience_LAmygdala | GM1: DMN_MPFC-Salience_LAmygdala | GN1: Salience_LInsula-Salience_LAmygdala | GO1: Salience_RInsula-Salience_LAmygdala | GP1: Attention_LDLPFC-Salience_RAmygdala | GQ1: Attention_RDLPFC-Salience_RAmygdala | GR1: Attention_LIPL-Salience_RAmygdala | GS1: Attention_RIPL-Salience_RAmygdala | GT1: Attention_mSPFC-Salience_RAmygdala | GU1: Attention_LPrecuneus-Salience_RAmygdala | GV1: Attention_RPrecuneus-Salience_RAmygdala | GW1: DMN_LAngularGyrus-Salience_RAmygdala | GX1: DMN_RAngularGyrus-Salience_RAmygdala | GY1: DMN_PCC-Salience_RAmygdala | GZ1: DMN_MPFC-Salience_RAmygdala | HA1: Salience_LInsula-Salience_RAmygdala | HB1: Salience_RInsula-Salience_RAmygdala | HC1: Salience_LAmygdala-Salience_RAmygdala
A2: epp270 | B2: =ABS(DC2) -> 0.58831806 | C2: =ABS(DD2) -> 0.17338755 | D2: =ABS(DE2) -> 0.072191101 | E2: =ABS(DF2) -> 0.23387851 | F2: =ABS(DG2) -> 0.20853883 | G2: =ABS(DH2) -> 0.51286114 | H2: =ABS(DI2) -> 0.33025175 | I2: =ABS(DJ2) -> 0.29828674 | ... DB2: =ABS(HC2) -> 0.830729 | DC2: 0.58831806 | DD2: 0.17338755 | DE2: 0.072191101 | DF2: -0.23387851 | DG2: -0.20853883 | DH2: 0.51286114 | DI2: 0.33025175 | DJ2: 0.29828674 | DK2: -0.31410515 | DL2: -0.26577205 | DM2: 0.12403889 | DN2: 0.099480986 | DO2: 0.63607592 | DP2: 0.31710779 | DQ2: -0.068564012 | DR2: 0.045680709 | DS2: 0.24963951 | DT2: 0.39463516 | DU2: 0.0013020917 | DV2: -0.0059745391 | DW2: 0.58452413 | DX2: -0.029652903 | DY2: -0.48810218 | DZ2: 0.23677453 | EA2: 0.26334115 | EB2: 0.026725824 | EC2: 0.12770892 | ED2: -0.085128366 | EE2: 0.10732256 | EF2: -0.20801852 | EG2: 0.13113582 | EH2: 0.16743091 | EI2: 0.26293281 | EJ2: -0.14050177 | EK2: -0.27190813 | EL2: 0.926853 | EM2: -0.073292358 | EN2: -0.21720226 | EO2: 0.019374446 | EP2: 0.23866158 | EQ2: -0.074428444 | ER2: -0.27026323 | ES2: -0.32152661 | ET2: 0.73429166 | EU2: 0.66895289 | EV2: 0.10872398 | EW2: -0.10053241 | EX2: -0.12476689 | EY2: -0.14032486 | EZ2: 0.23596883 | FA2: -0.27110495 | FB2: -0.35144027 | FC2: 0.67013567 | FD2: 0.76102201 | FE2: 0.76566125 | FF2: -0.09179144 | FG2: 0.12809837 | FH2: -0.28756996 | FI2: -0.23701888 | FJ2: 0.33678252 | FK2: -0.15021865 | FL2: -0.019815762 | FM2: -0.36406677 | FN2: -0.15972329 | FO2: -0.44840262 | FP2: -0.23260459 | FQ2: 0.21203314 | FR2: 0.50478525 | FS2: -0.023898434 | FT2: -0.041413161 | FU2: 0.13759314 | FV2: -0.065293329 | FW2: 0.27615433 | FX2: -0.74381622 | FY2: -0.3613075 | FZ2: -0.59321608 | GA2: -0.51504866 | GB2: 0.4519716 | GC2: -0.17219024 | GD2: -0.19070761 | GE2: -0.099556789 | GF2: -0.34795873 | GG2: -0.24194428 | GH2: -0.39097136 | GI2: -0.048595001 | GJ2: 0.17169178 | GK2: 0.047654259 | GL2: 0.15973777 | GM2: 0.22726389 | GN2: 0.24789284 | GO2: -0.15755834 | GP2: -0.094514181 | GQ2: -0.17672336 | GR2: 0.098704337 | GS2: -0.11188243 | GT2: -0.30012641 | GU2: -0.30674262 | GV2: 0.031158094 | GW2: 0.19121499 | GX2: 0.13117221 | GY2: 0.27026612 | GZ2: 0.1130046 | HA2: 0.0095128376 | HB2: -0.25332859 | HC2: 0.830729
A3: epp271 | B3: =ABS(DC3) -> 0.68196735 | C3: =ABS(DD3) -> 0.93383991 | D3: =ABS(DE3) -> 0.40305199 | E3: =ABS(DF3) -> 0.39512777 | F3: =ABS(DG3) -> 0.12439533 | G3: =ABS(DH3) -> 0.67708222 | H3: =ABS(DI3) -> 0.33637444 | I3: =ABS(DJ3) -> 0.34832056 | ... DB3: =ABS(HC3) -> 0.78594093 | DC3: 0.68196735 | DD3: 0.93383991 | DE3: 0.40305199 | DF3: 0.39512777 | DG3: 0.12439533 | DH3: 0.67708222 | DI3: 0.33637444 | DJ3: 0.34832056 | DK3: 0.36635884 | DL3: 0.20654943 | DM3: 0.43424264 | DN3: 0.25473325 | DO3: 0.49406934 | DP3: 0.27453418 | DQ3: 0.14907354 | DR3: 0.3144537 | DS3: 0.25561006 | DT3: 0.36973145 | DU3: 0.43905778 | DV3: 0.19525087 | DW3: 0.83744292 | DX3: -0.17032754 | DY3: -0.41536846 | DZ3: -0.028744248 | EA3: 0.57935561 | EB3: 0.10149138 | EC3: -0.15857833 | ED3: -0.0085469305 | EE3: 0.48984124 | EF3: 0.25064219 | EG3: 0.56518439 | EH3: 0.54236716 | EI3: -0.082110338 | EJ3: 0.427827 | EK3: 0.21922763 | EL3: 0.11231458 | EM3: -0.3356985 | EN3: -0.32110632 | EO3: -0.21323112 | EP3: 0.48618716 | EQ3: 0.17385122 | ER3: -0.090915736 | ES3: 0.13693071 | ET3: 1.2457731 | EU3: -0.051381004 | EV3: -0.31109457 | EW3: -0.24835665 | EX3: -0.35503903 | EY3: 0.21076935 | EZ3: 0.16505915 | FA3: -0.062861038 | FB3: 0.041703873 | FC3: 0.64562684 | FD3: -0.08648428 | FE3: 0.7788738 | FF3: 0.77639848 | FG3: 0.51606527 | FH3: 0.5756063 | FI3: 0.14968696 | FJ3: 0.48123322 | FK3: 0.12130618 | FL3: 0.10184782 | FM3: -0.25552318 | FN3: 0.11796536 | FO3: -0.38988394 | FP3: -0.3072754 | FQ3: 0.4378798 | FR3: 0.56601215 | FS3: 0.2370445 | FT3: -0.1532271 | FU3: 0.43292867 | FV3: 0.10141967 | FW3: 0.087238434 | FX3: -0.3357689 | FY3: -0.072002863 | FZ3: -0.36094313 | GA3: -0.17307681 | GB3: 1.1078321 | GC3: 0.28291219 | GD3: -0.052484705 | GE3: 0.13456923 | GF3: 0.034180887 | GG3: -0.31654707 | GH3: 0.18958511 | GI3: 0.11121025 | GJ3: -0.15736397 | GK3: 0.31898886 | GL3: -0.31737938 | GM3: -0.16616414 | GN3: 0.10317159 | GO3: -0.041979595 | GP3: 0.38318517 | GQ3: 0.19143505 | GR3: 0.1570002 | GS3: -0.15541713 | GT3: -0.35979554 | GU3: 0.10780169 | GV3: -0.085157936 | GW3: -0.35642728 | GX3: 0.26123016 | GY3: -0.64871586 | GZ3: -0.25671659 | HA3: 0.27748336 | HB3: 0.20175447 | HC3: 0.78594093
A4: epp278 | B4: =ABS(DC4) -> 0.35729372 | C4: =ABS(DD4) -> 0.17511072 | D4: =ABS(DE4) -> 0.024300331 | E4: =ABS(DF4) -> 0.088633153 | F4: =ABS(DG4) -> 0.32168803 | G4: =ABS(DH4) -> 0.3991937 | H4: =ABS(DI4) -> 0.19560883 | I4: =ABS(DJ4) -> 0.20361803 | ... DB4: =ABS(HC4) -> 0.53217642 | DC4: 0.35729372 | DD4: 0.17511072 | DE4: -0.024300331 | DF4: -0.088633153 | DG4: 0.32168803 | DH4: 0.3991937 | DI4: 0.19560883 | DJ4: 0.20361803 | DK4: 0.42081385 | DL4: 0.1739224 | DM4: 0.17290857 | DN4: -0.019297786 | DO4: 0.16871445 | DP4: 0.24363642 | DQ4: 0.19661683 | DR4: 0.21362103 | DS4: 0.51288267 | DT4: 0.013315749 | DU4: 0.38943942 | DV4: 0.060074118 | DW4: 0.6886409 | DX4: -0.076524639 | DY4: -0.01852034 | DZ4: -0.27895905 | EA4: -0.25795433 | EB4: -0.015670377 | EC4: -0.28644012 | ED4: -0.2426981 | EE4: -0.05529336 | EF4: 0.052513889 | EG4: -0.13154637 | EH4: -0.10341456 | EI4: 0.013330785 | EJ4: -0.15465097 | EK4: -0.25768493 | EL4: 0.72049183 | EM4: -0.16447936 | EN4: -0.19947556 | EO4: -0.11766085 | EP4: -0.55762736 | EQ4: -0.045354164 | ER4: -0.22522314 | ES4: -0.32782718 | ET4: 0.61727511 | EU4: 0.42009492 | EV4: -0.15172758 | EW4: -0.22316196 | EX4: -0.23426357 | EY4: -0.069271359 | EZ4: -0.081236799 | FA4: 0.37648774 | FB4: 0.13061653 | FC4: 0.094484372 | FD4: 0.24050756 | FE4: 0.18193651 | FF4: 0.47027063 | FG4: 0.11420009 | FH4: 0.22222031 | FI4: 0.15288099 | FJ4: 0.28985883 | FK4: 0.072392135 | FL4: 0.05885458 | FM4: -0.33793852 | FN4: -0.36414542 | FO4: -0.39593182 | FP4: 0.030067688 | FQ4: 0.33524266 | FR4: 0.24550495 | FS4: 0.28958215 | FT4: 0.41697097 | FU4: 0.26408308 | FV4: 0.078558621 | FW4: 0.20541624 | FX4: -0.34433808 | FY4: -0.49507188 | FZ4: -0.58981394 | GA4: -0.20145768 | GB4: 0.81686182 | GC4: 0.16500335 | GD4: 0.022819086 | GE4: -0.026447693 | GF4: 0.064807661 | GG4: -0.24416842 | GH4: 0.34376753 | GI4: 0.3151268 | GJ4: -0.3298484 | GK4: -0.172421 | GL4: -0.32468482 | GM4: 0.52566806 | GN4: 0.18301659 | GO4: 0.15309699 | GP4: 0.053401678 | GQ4: -0.13957344 | GR4: -0.23382297 | GS4: -0.026834233 | GT4: -0.36224536 | GU4: 0.01889441 | GV4: 0.022899713 | GW4: -0.24741254 | GX4: 0.0050332922 | GY4: -0.21465274 | GZ4: 0.23809167 | HA4: 0.22658036 | HB4: -0.011313267 | HC4: 0.53217642
A5: epp309 | B5: =ABS(DC5) -> 0.64836151 | C5: =ABS(DD5) -> 0.6281664 | D5: =ABS(DE5) -> 0.79946454 | E5: =ABS(DF5) -> 0.24559607 | F5: =ABS(DG5) -> 0.9242259 | G5: =ABS(DH5) -> 0.87890665 | H5: =ABS(DI5) -> 0.30322952 | I5: =ABS(DJ5) -> 0.14202156 | ... DB5: =ABS(HC5) -> 0.66241268 | DC5: 0.64836151 | DD5: 0.6281664 | DE5: 0.79946454 | DF5: 0.24559607 | DG5: 0.9242259 | DH5: 0.87890665 | DI5: 0.30322952 | DJ5: 0.14202156 | DK5: 0.23167141 | DL5: 0.0418291 | DM5: 0.07992888 | DN5: 0.11885831 | DO5: 0.098346978 | DP5: 0.072789022 | DQ5: -0.049718728 | DR5: -0.0013412611 | DS5: 0.56030689 | DT5: 0.40463569 | DU5: 0.8409981 | DV5: -0.092726476 | DW5: 0.53161016 | DX5: 0.32742291 | DY5: -0.067032122 | DZ5: -0.0026396891 | EA5: -0.087357863 | EB5: 0.31597259 | EC5: -0.21892491 | ED5: -0.39345399 | EE5: 0.096987252 | EF5: -0.051925256 | EG5: -0.084090765 | EH5: 0.078810435 | EI5: -0.046825634 | EJ5: -0.062633688 | EK5: -0.026378015 | EL5: 0.82157237 | EM5: 0.12059856 | EN5: -0.20152814 | EO5: -0.19201696 | EP5: -0.090487746 | EQ5: 0.14007116 | ER5: -0.11779689 | ES5: -0.20106907 | ET5: 0.62658692 | EU5: 0.53991529 | EV5: 0.39172102 | EW5: -0.042401552 | EX5: -0.0037479407 | EY5: -0.085897386 | EZ5: 0.12874739 | FA5: -0.031186492 | FB5: -0.29713701 | FC5: 0.70502773 | FD5: 0.54701286 | FE5: 0.93518593 | FF5: 0.18687025 | FG5: 0.11560219 | FH5: 0.16495784 | FI5: 0.097755494 | FJ5: 0.38338364 | FK5: 0.42234937 | FL5: 0.088112796 | FM5: -0.10657951 | FN5: -0.29737216 | FO5: -0.22758332 | FP5: -0.012527827 | FQ5: -0.00019363904 | FR5: 0.1156286 | FS5: 0.065056093 | FT5: 0.10792277 | FU5: 0.3077399 | FV5: 0.44113139 | FW5: 0.14491112 | FX5: -0.12673075 | FY5: -0.25468032 | FZ5: -0.11520384 | GA5: -0.16062481 | GB5: 0.79106732 | GC5: 0.30400728 | GD5: -0.18136417 | GE5: -0.095467456 | GF5: -0.14410069 | GG5: 0.11730216 | GH5: 0.0017183394 | GI5: -0.22585208 | GJ5: 0.32782317 | GK5: 0.18046927 | GL5: 0.26112453 | GM5: 0.39250944 | GN5: 0.13552968 | GO5: 0.024180202 | GP5: 0.10434896 | GQ5: -0.12571273 | GR5: -0.0039435776 | GS5: 0.15459349 | GT5: -0.0091066382 | GU5: -0.029985342 | GV5: 0.0023257552 | GW5: 0.2628454 | GX5: 0.24508629 | GY5: 0.17384901 | GZ5: 0.15662106 | HA5: 0.034030189 | HB5: -0.040888455 | HC5: 0.66241268
A6: epp314 | B6: =ABS(DC6) -> 0.041227644 | C6: =ABS(DD6) -> 0.32485668 | D6: =ABS(DE6) -> 0.329995 | E6: =ABS(DF6) -> 0.088605081 | F6: =ABS(DG6) -> 0.51101269 | G6: =ABS(DH6) -> 0.21307723 | H6: =ABS(DI6) -> 0.32683853 | I6: =ABS(DJ6) -> 0.15874563 | ... DB6: =ABS(HC6) -> 0.90235082 | DC6: -0.041227644 | DD6: 0.32485668 | DE6: -0.329995 | DF6: 0.088605081 | DG6: 0.51101269 | DH6: 0.21307723 | DI6: 0.32683853 | DJ6: 0.15874563 | DK6: -0.0052281172 | DL6: 0.036207613 | DM6: -0.010240051 | DN6: -0.50339251 | DO6: 0.28823734 | DP6: -0.18619021 | DQ6: -0.33492923 | DR6: -0.39146884 | DS6: 0.073526366 | DT6: 0.19280626 | DU6: 0.60469517 | DV6: -0.14746684 | DW6: 0.27825033 | DX6: 0.44536448 | DY6: -0.053747917 | DZ6: 0.22224194 | EA6: 0.079844883 | EB6: -0.2869617 | EC6: 0.29280052 | ED6: -0.22210092 | EE6: 0.059103482 | EF6: -0.25063074 | EG6: 0.095346127 | EH6: -0.062097916 | EI6: -0.17928575 | EJ6: 0.35415187 | EK6: -0.18840091 | EL6: 0.7518288 | EM6: 0.30196792 | EN6: 0.22585223 | EO6: 0.13071411 | EP6: 0.24360041 | EQ6: -0.22194754 | ER6: -0.041880093 | ES6: 0.029088182 | ET6: 0.58391929 | EU6: 0.16887245 | EV6: 0.14576277 | EW6: 0.44381436 | EX6: -0.39670618 | EY6: 0.08264407 | EZ6: -0.12097856 | FA6: -0.15320411 | FB6: -0.17638318 | FC6: 0.20381877 | FD6: 0.0048516733 | FE6: 0.53722689 | FF6: -0.13869369 | FG6: 0.066273285 | FH6: -0.24828027 | FI6: -0.23062304 | FJ6: 0.5409462 | FK6: -0.1618306 | FL6: 0.086566856 | FM6: -0.65045314 | FN6: -0.45413689 | FO6: -0.16863615 | FP6: -0.068717168 | FQ6: -0.4220234 | FR6: 0.16462623 | FS6: -0.24066628 | FT6: -0.10043579 | FU6: 0.37036235 | FV6: -0.37562378 | FW6: 0.22732531 | FX6: -0.92989368 | FY6: -0.52656035 | FZ6: -0.3514421 | GA6: -0.17819252 | GB6: 0.8865902 | GC6: 0.066894086 | GD6: 0.033025866 | GE6: 0.19049956 | GF6: 0.38216585 | GG6: 0.074069145 | GH6: -0.1288647 | GI6: 0.16835853 | GJ6: 0.035093081 | GK6: 0.093344667 | GL6: 0.17165047 | GM6: 0.18076899 | GN6: 0.028446693 | GO6: 0.061230527 | GP6: -0.20451037 | GQ6: 0.079144249 | GR6: 0.16470373 | GS6: 0.38063308 | GT6: 0.07650979 | GU6: -0.15850266 | GV6: 0.37888338 | GW6: -0.13904748 | GX6: 0.044888147 | GY6: 0.17164385 | GZ6: 0.021828725 | HA6: 0.14813962 | HB6: 0.31657009 | HC6: 0.90235082
A7: epp321 | B7: =ABS(DC7) -> 0.48582124 | C7: =ABS(DD7) -> 0.3443556 | D7: =ABS(DE7) -> 0.039622854 | E7: =ABS(DF7) -> 0.32982661 | F7: =ABS(DG7) -> 0.81572136 | G7: =ABS(DH7) -> 0.10716201 | H7: =ABS(DI7) -> 0.17194923 | I7: =ABS(DJ7) -> 0.0010248855 | ... DB7: =ABS(HC7) -> 0.66125207 | DC7: 0.48582124 | DD7: 0.3443556 | DE7: -0.039622854 | DF7: 0.32982661 | DG7: 0.81572136 | DH7: 0.10716201 | DI7: 0.17194923 | DJ7: -0.0010248855 | DK7: 0.20842119 | DL7: -0.13770729 | DM7: 0.0016003381 | DN7: 0.16178729 | DO7: 0.0264467 | DP7: 0.30704011 | DQ7: -0.34816616 | DR7: 0.040462568 | DS7: 0.14180103 | DT7: 0.2383362 | DU7: 0.33709073 | DV7: -0.19067241 | DW7: 0.69702328 | DX7: -0.15730542 | DY7: -0.15640136 | DZ7: -0.027259525 | EA7: -0.068936981 | EB7: -0.16421619 | EC7: -0.098302503 | ED7: -0.10704843 | EE7: -0.17199598 | EF7: -0.070971671 | EG7: -0.061858987 | EH7: -0.18008188 | EI7: -0.065900245 | EJ7: -0.15253358 | EK7: -0.29862235 | EL7: 0.57370861 | EM7: -0.13971408 | EN7: 0.11681502 | EO7: -0.049538323 | EP7: 0.097852492 | EQ7: 0.11925565 | ER7: -0.0514204 | ES7: -0.069842167 | ET7: 0.4545888 | EU7: 0.53453271 | EV7: 0.15386022 | EW7: 0.073253843 | EX7: 0.047811235 | EY7: 0.26128055 | EZ7: -0.25278909 | FA7: 0.39444172 | FB7: 0.18326638 | FC7: 0.16867037 | FD7: -0.17380045 | FE7: 0.088849093 | FF7: -0.1199485 | FG7: -0.22996864 | FH7: 0.11138352 | FI7: -0.36302593 | FJ7: 0.59997946 | FK7: -0.24006633 | FL7: -0.077918998 | FM7: -0.23614682 | FN7: -0.12128778 | FO7: -0.18526731 | FP7: -0.1851862 | FQ7: -0.45800747 | FR7: 0.035028903 | FS7: -0.16635102 | FT7: -0.20168413 | FU7: -0.021303177 | FV7: -0.059642648 | FW7: -0.031827768 | FX7: -0.26565843 | FY7: 0.0038979184 | FZ7: -0.27879001 | GA7: -0.36378526 | GB7: 0.52734256 | GC7: 0.033704113 | GD7: 0.17046123 | GE7: 0.084975726 | GF7: 0.11158961 | GG7: 0.0051930932 | GH7: -0.010593928 | GI7: 0.20424714 | GJ7: -0.18484241 | GK7: 0.10623941 | GL7: 0.39441004 | GM7: -0.098064321 | GN7: 0.15087853 | GO7: 0.18117084 | GP7: 0.10282472 | GQ7: 0.24889252 | GR7: 0.0039695681 | GS7: 0.19467135 | GT7: -0.15044928 | GU7: 0.14144725 | GV7: 0.20335588 | GW7: -0.11185088 | GX7: 0.30927374 | GY7: 0.2545368 | GZ7: -0.098592575 | HA7: -0.072196678 | HB7: 0.02269713 | HC7: 0.66125207
A8: epp322 | B8: =ABS(DC8) -> 0.96252593 | C8: =ABS(DD8) -> 0.81687447 | D8: =ABS(DE8) -> 0.39329418 | E8: =ABS(DF8) -> 0.43364273 | F8: =ABS(DG8) -> 0.18896124 | G8: =ABS(DH8) -> 0.78836485 | H8: =ABS(DI8) -> 0.0025033124 | I8: =ABS(DJ8) -> 0.0066809477 | ... DB8: =ABS(HC8) -> 0.65873372 | DC8: 0.96252593 | DD8: 0.81687447 | DE8: 0.39329418 | DF8: 0.43364273 | DG8: 0.18896124 | DH8: 0.78836485 | DI8: -0.0025033124 | DJ8: 0.0066809477 | DK8: -0.3413278 | DL8: -0.53346402 | DM8: 0.61980899 | DN8: 0.43854753 | DO8: 0.52535045 | DP8: 0.055438491 | DQ8: -0.056955601 | DR8: 0.046616375 | DS8: 0.089907523 | DT8: 0.13899967 | DU8: -0.2801592 | DV8: 0.088554628 | DW8: 0.90089379 | DX8: -0.057230546 | DY8: -0.36894506 | DZ8: 0.22170685 | EA8: 0.13124323 | EB8: -0.26100228 | EC8: 0.12171348 | ED8: 0.042605374 | EE8: 0.07237914 | EF8: 0.12678788 | EG8: 0.046052055 | EH8: -0.30636351 | EI8: 0.10379207 | EJ8: 0.51030421 | EK8: 0.51212813 | EL8: 0.27189891 | EM8: -0.59276766 | EN8: -0.83456372 | EO8: -0.064845467 | EP8: 0.15674237 | EQ8: -0.17585163 | ER8: -0.50380473 | ES8: -0.22621401 | ET8: 0.50928074 | EU8: -0.25440967 | EV8: -0.51730639 | EW8: -0.53858084 | EX8: -0.095988483 | EY8: -0.022528543 | EZ8: -0.080747147 | FA8: -0.14429613 | FB8: 0.0090074214 | FC8: 0.52813479 | FD8: 0.017356637 | FE8: 0.78722786 | FF8: 0.2972232 | FG8: 0.28574909 | FH8: 0.16106702 | FI8: -0.16443959 | FJ8: 0.44176407 | FK8: 0.35684439 | FL8: 0.30256171 | FM8: -0.42216459 | FN8: 0.072560782 | FO8: -0.45366071 | FP8: -0.22955267 | FQ8: -0.25879993 | FR8: -0.15525666 | FS8: -0.44895567 | FT8: -0.63765295 | FU8: 0.81211079 | FV8: -0.090325655 | FW8: 0.18869911 | FX8: -0.36941484 | FY8: -0.045500955 | FZ8: -0.19285667 | GA8: -0.10785095 | GB8: 0.63704332 | GC8: -0.29032867 | GD8: -0.25019549 | GE8: -0.14076069 | GF8: -0.19470823 | GG8: -0.16583128 | GH8: 0.0027989481 | GI8: 0.19864329 | GJ8: 0.065113937 | GK8: -0.018053864 | GL8: 0.091562718 | GM8: 0.15403074 | GN8: -0.2088786 | GO8: 0.045696266 | GP8: -0.3925774 | GQ8: -0.35534181 | GR8: -0.28789485 | GS8: -0.15544783 | GT8: -0.29305599 | GU8: -0.05965978 | GV8: 0.090130456 | GW8: 0.096623102 | GX8: 0.022562463 | GY8: 0.16522511 | GZ8: 0.27847858 | HA8: -0.25770716 | HB8: 0.0050129958 | HC8: 0.65873372
A9: epp330 | B9: =ABS(DC9) -> 0.62684832 | C9: =ABS(DD9) -> 0.65508534 | D9: =ABS(DE9) -> 0.57953876 | E9: =ABS(DF9) -> 0.035797792 | F9: =ABS(DG9) -> 0.27782525 | G9: =ABS(DH9) -> 0.60254934 | H9: =ABS(DI9) -> 0.12003566 | I9: =ABS(DJ9) -> 0.19100387 | ... DB9: =ABS(HC9) -> 0.38111658 | DC9: 0.62684832 | DD9: 0.65508534 | DE9: 0.57953876 | DF9: -0.035797792 | DG9: 0.27782525 | DH9: 0.60254934 | DI9: -0.12003566 | DJ9: -0.19100387 | DK9: -0.20679776 | DL9: -0.40484219 | DM9: 0.7149551 | DN9: 0.31803194 | DO9: 0.47639935 | DP9: -0.065629452 | DQ9: 0.082016892 | DR9: 0.25346361 | DS9: 0.21295484 | DT9: 0.053271045 | DU9: -0.18535954 | DV9: 0.097289851 | DW9: 0.6470467 | DX9: 0.033636071 | DY9: 0.021942764 | DZ9: 0.14161952 | EA9: 0.1878358 | EB9: -0.058191441 | EC9: 0.41481295 | ED9: 0.04022003 | EE9: 0.26399468 | EF9: 0.19981707 | EG9: 0.29639481 | EH9: 0.18401674 | EI9: -0.11221412 | EJ9: 0.49025279 | EK9: 0.3245673 | EL9: 0.67352622 | EM9: -0.43122073 | EN9: -0.12127534 | EO9: 0.038107863 | EP9: 0.46637273 | EQ9: 0.012191849 | ER9: -0.34515302 | ES9: -0.49045003 | ET9: 0.28428475 | EU9: -0.074489924 | EV9: -0.25959188 | EW9: 0.11288889 | EX9: 0.141561 | EY9: 0.46947655 | EZ9: 0.001478317 | FA9: -0.090455502 | FB9: -0.2927086 | FC9: 0.63744356 | FD9: 0.24261094 | FE9: 0.72842305 | FF9: -0.056468259 | FG9: 0.098942208 | FH9: 0.062910987 | FI9: 0.26698841 | FJ9: 0.095841068 | FK9: -0.29158298 | FL9: -0.10170528 | FM9: -0.12639931 | FN9: -0.19273095 | FO9: 0.046327964 | FP9: 0.080494513 | FQ9: 0.22628426 | FR9: 0.12927366 | FS9: -0.048175336 | FT9: -0.081712913 | FU9: 0.02807465 | FV9: -0.026148548 | FW9: 0.30831251 | FX9: -0.46554668 | FY9: -0.19736091 | FZ9: -0.5096725 | GA9: -0.57003267 | GB9: 0.44080191 | GC9: -0.014129111 | GD9: 0.24744099 | GE9: 0.052905654 | GF9: 0.16691396 | GG9: 0.049104936 | GH9: -0.23535876 | GI9: -0.216582 | GJ9: -0.031756714 | GK9: -0.16545132 | GL9: 0.14260867 | GM9: 0.29773926 | GN9: 0.58313166 | GO9: 0.060079903 | GP9: 0.015401122 | GQ9: 0.15318524 | GR9: 0.01524051 | GS9: -0.16507241 | GT9: 0.18723956 | GU9: -0.022591603 | GV9: 0.086841809 | GW9: -0.33802729 | GX9: -0.21791187 | GY9: -0.19267043 | GZ9: -0.15669649 | HA9: 0.28643802 | HB9: 0.47168224 | HC9: 0.38111658
A10: epp337 | B10: =ABS(DC10) -> 0.40938966 | C10: =ABS(DD10) -> 0.88735978 | D10: =ABS(DE10) -> 0.39299555 | E10: =ABS(DF10) -> 0.40144003 | F10: =ABS(DG10) -> 0.52459264 | G10: =ABS(DH10) -> 0.46662408 | H10: =ABS(DI10) -> 0.11954478 | I10: =ABS(DJ10) -> 0.33675196 | ... DB10: =ABS(HC10) -> 1.117868 | DC10: 0.40938966 | DD10: 0.88735978 | DE10: 0.39299555 | DF10: 0.40144003 | DG10: 0.52459264 | DH10: 0.46662408 | DI10: -0.11954478 | DJ10: 0.33675196 | DK10: 0.062302514 | DL10: -0.10802725 | DM10: 0.070562396 | DN10: -0.013539892 | DO10: 0.18782389 | DP10: 0.16866595 | DQ10: 0.17192951 | DR10: -0.165853 | DS10: 0.20325127 | DT10: -0.067626058 | DU10: 0.18967951 | DV10: 0.27874857 | DW10: 1.085156 | DX10: -0.069846858 | DY10: -0.40245058 | DZ10: -0.16070231 | EA10: -0.13973137 | EB10: -0.43678646 | EC10: 0.10148724 | ED10: -0.045582096 | EE10: -0.0080845715 | EF10: -0.17929896 | EG10: -0.2297787 | EH10: 0.080863792 | EI10: -0.36459161 | EJ10: 0.055667489 | EK10: 0.041310292 | EL10: 0.98086935 | EM10: -0.16982491 | EN10: -0.2856659 | EO10: -0.19028955 | EP10: 0.032044616 | EQ10: -0.44830055 | ER10: 0.052769926 | ES10: -0.01543663 | ET10: 0.86913501 | EU10: 1.1155194 | EV10: -0.17889841 | EW10: -0.25294793 | EX10: -0.27783505 | EY10: -0.011408045 | EZ10: 0.095960772 | FA10: 0.35498841 | FB10: 0.29465807 | FC10: 0.41871633 | FD10: 0.298646 | FE10: 0.25620827 | FF10: 0.19634922 | FG10: 0.21280709 | FH10: 0.11022917 | FI10: -0.2833857 | FJ10: 0.46502047 | FK10: -0.030967121 | FL10: -0.024399204 | FM10: -0.34553813 | FN10: -0.36848006 | FO10: -0.52372161 | FP10: -0.17861282 | FQ10: -0.15918883 | FR10: 0.34317167 | FS10: 0.079015253 | FT10: -0.11886765 | FU10: 0.64285546 | FV10: 0.11185998 | FW10: 0.32544155 | FX10: -0.32438134 | FY10: -0.40408532 | FZ10: -0.51082507 | GA10: 0.018859067 | GB10: 0.63968977 | GC10: -0.10052694 | GD10: 0.25275629 | GE10: 0.17776912 | GF10: -0.13548464 | GG10: 0.26153628 | GH10: 0.069911202 | GI10: 0.12878314 | GJ10: -0.03684478 | GK10: -0.030581799 | GL10: -0.13339159 | GM10: -0.071600193 | GN10: 0.28940846 | GO10: 0.52014849 | GP10: -0.072795102 | GQ10: 0.34466593 | GR10: 0.21389702 | GS10: -0.14356059 | GT10: 0.27566303 | GU10: 0.13709744 | GV10: 0.2199884 | GW10: -0.35618417 | GX10: -0.35992629 | GY10: -0.39061983 | GZ10: -0.24026396 | HA10: 0.43326032 | HB10: 0.62071646 | HC10: 1.117868
A11: epp344 | B11: =ABS(DC11) -> 0.52781828 | C11: =ABS(DD11) -> 0.18767764 | D11: =ABS(DE11) -> 0.10833036 | E11: =ABS(DF11) -> 0.092145598 | F11: =ABS(DG11) -> 0.27079686 | G11: =ABS(DH11) -> 0.090487735 | H11: =ABS(DI11) -> 0.32510323 | I11: =ABS(DJ11) -> 0.14926595 | ... DB11: =ABS(HC11) -> 0.32859893 | DC11: 0.52781828 | DD11: 0.18767764 | DE11: 0.10833036 | DF11: -0.092145598 | DG11: 0.27079686 | DH11: 0.090487735 | DI11: 0.32510323 | DJ11: 0.14926595 | DK11: -0.22145757 | DL11: -0.22461909 | DM11: -0.15903359 | DN11: -0.20352112 | DO11: 0.098108087 | DP11: 0.38555483 | DQ11: -0.18190581 | DR11: -0.037058359 | DS11: 0.11755305 | DT11: 0.22317514 | DU11: 0.11981137 | DV11: -0.14609952 | DW11: 0.2302465 | DX11: 0.047189812 | DY11: -0.056528749 | DZ11: 0.15854376 | EA11: 0.5397148 | EB11: -0.58330243 | EC11: 0.38498782 | ED11: 0.037445395 | EE11: -0.040393155 | EF11: 0.080096004 | EG11: 0.020224674 | EH11: 0.46748354 | EI11: -0.39626057 | EJ11: 0.22583198 | EK11: 0.48352757 | EL11: 0.48492464 | EM11: -0.20413059 | EN11: 0.016682502 | EO11: 0.064023788 | EP11: 0.46427895 | EQ11: -0.53089287 | ER11: 0.27895356 | ES11: 0.25517222 | ET11: 0.68705168 | EU11: 0.53077787 | EV11: -0.080715424 | EW11: 0.12708669 | EX11: -0.03734025 | EY11: 0.40524964 | EZ11: -0.213636 | FA11: 0.36357609 | FB11: 0.092684939 | FC11: 0.49405235 | FD11: 0.21732867 | FE11: 0.66897654 | FF11: 0.48043691 | FG11: 0.35024411 | FH11: -0.060164886 | FI11: -0.15697313 | FJ11: 0.38599611 | FK11: -0.23753241 | FL11: -0.18050085 | FM11: -0.30742033 | FN11: -0.14289148 | FO11: -0.2502035 | FP11: -0.026495449 | FQ11: 0.2403196 | FR11: 0.42846934 | FS11: -0.0155012 | FT11: 0.21515724 | FU11: 0.20329362 | FV11: 0.066147171 | FW11: -0.35722724 | FX11: -0.1268978 | FY11: -0.1307982 | FZ11: -0.27364716 | GA11: -0.018270257 | GB11: 0.6598139 | GC11: 0.12623432 | GD11: -0.21988624 | GE11: 0.12303973 | GF11: -0.004679312 | GG11: 0.090256588 | GH11: -0.077363343 | GI11: -0.35408333 | GJ11: 0.15480217 | GK11: -0.22539862 | GL11: -0.082506806 | GM11: 0.053889262 | GN11: 0.18687826 | GO11: 0.10480489 | GP11: 0.045602973 | GQ11: -0.12090214 | GR11: 0.03633977 | GS11: -0.39656697 | GT11: 0.013017138 | GU11: -0.11544832 | GV11: -0.28607707 | GW11: -0.38459424 | GX11: -0.50739868 | GY11: -0.36607611 | GZ11: -0.31131432 | HA11: 0.17083486 | HB11: -0.0028866808 | HC11: 0.32859893
A12: epp348 | B12: =ABS(DC12) -> 0.48149378 | C12: =ABS(DD12) -> 0.6443512 | D12: =ABS(DE12) -> 0.64447851 | E12: =ABS(DF12) -> 0.21855582 | F12: =ABS(DG12) -> 1.0991067 | G12: =ABS(DH12) -> 0.71385829 | H12: =ABS(DI12) -> 0.19705619 | I12: =ABS(DJ12) -> 0.21678365 | ... DB12: =ABS(HC12) -> 0.98479028 | DC12: 0.48149378 | DD12: 0.6443512 | DE12: 0.64447851 | DF12: 0.21855582 | DG12: 1.0991067 | DH12: 0.71385829 | DI12: 0.19705619 | DJ12: 0.21678365 | DK12: 0.44132225 | DL12: 0.24679883 | DM12: 0.60952988 | DN12: 0.50661799 | DO12: 0.53500292 | DP12: 0.37571928 | DQ12: 0.04587733 | DR12: 0.02744795 | DS12: 0.18484547 | DT12: 0.026105103 | DU12: 0.10228209 | DV12: 0.033995304 | DW12: 0.42134627 | DX12: -0.14626492 | DY12: -0.36616225 | DZ12: -0.55944315 | EA12: -0.45983477 | EB12: -0.31003637 | EC12: -0.12207047 | ED12: 0.16103661 | EE12: -0.15652164 | EF12: -0.032185635 | EG12: -0.25394405 | EH12: 0.072421135 | EI12: -0.30458906 | EJ12: 0.08870163 | EK12: -0.14571103 | EL12: 0.37562136 | EM12: -0.019329915 | EN12: -0.16535064 | EO12: -0.10934934 | EP12: -0.17797306 | EQ12: -0.15151692 | ER12: -0.059442642 | ES12: 0.0049044927 | ET12: 0.6421734 | EU12: 0.20467727 | EV12: -0.20716272 | EW12: -0.53407179 | EX12: -0.61724242 | EY12: -0.57815033 | EZ12: -0.27734272 | FA12: -0.50220895 | FB12: -0.089613754 | FC12: 0.67129803 | FD12: 0.11535814 | FE12: 0.51279559 | FF12: -0.17138803 | FG12: -0.11841703 | FH12: -0.18232735 | FI12: -0.13201032 | FJ12: 0.066357362 | FK12: -0.41469532 | FL12: -0.29536023 | FM12: -0.26767842 | FN12: 0.052692303 | FO12: -0.11057092 | FP12: 0.20547963 | FQ12: -0.053825421 | FR12: -0.26826495 | FS12: -0.11987415 | FT12: -0.20566083 | FU12: 0.20034957 | FV12: -0.22569421 | FW12: -0.033822961 | FX12: -0.13333569 | FY12: -0.27183095 | FZ12: 0.05488226 | GA12: 0.20656848 | GB12: 0.54649198 | GC12: -0.28049982 | GD12: 0.059866505 | GE12: -0.15493399 | GF12: 0.084106547 | GG12: -0.12015914 | GH12: 0.1442684 | GI12: 0.13506121 | GJ12: 0.11106249 | GK12: 0.46591988 | GL12: -0.17641335 | GM12: -0.037569923 | GN12: 0.1135386 | GO12: -0.12751266 | GP12: -0.17873779 | GQ12: -0.092344529 | GR12: -0.12858349 | GS12: -0.1261167 | GT12: -0.12294522 | GU12: 0.021583231 | GV12: -0.027042129 | GW12: 0.11614562 | GX12: 0.38955475 | GY12: -0.15926215 | GZ12: 0.0098680981 | HA12: 0.2404665 | HB12: -0.16815678 | HC12: 0.98479028
A13: epp350 | B13: =ABS(DC13) -> 0.35448019 | C13: =ABS(DD13) -> 0.35520375 | D13: =ABS(DE13) -> 0.57369835 | E13: =ABS(DF13) -> 0.14393636 | F13: =ABS(DG13) -> 0.44180737 | G13: =ABS(DH13) -> 0.55768799 | H13: =ABS(DI13) -> 0.18249922 | I13: =ABS(DJ13) -> 0.075680069 | ... DB13: =ABS(HC13) -> 0.59483651 | DC13: 0.35448019 | DD13: 0.35520375 | DE13: 0.57369835 | DF13: 0.14393636 | DG13: 0.44180737 | DH13: 0.55768799 | DI13: 0.18249922 | DJ13: 0.075680069 | DK13: 0.031789478 | DL13: -0.3019876 | DM13: 0.0058190848 | DN13: -0.011102302 | DO13: 0.44481106 | DP13: -0.04193953 | DQ13: 0.17087917 | DR13: 0.032178353 | DS13: 0.27188833 | DT13: 0.43221282 | DU13: 0.20406073 | DV13: -0.021208138 | DW13: 0.73003506 | DX13: 0.15212357 | DY13: -0.17377872 | DZ13: 0.02625788 | EA13: -0.10879231 | EB13: 0.14685006 | EC13: 0.12339043 | ED13: -0.088792533 | EE13: -0.13184306 | EF13: -0.099517968 | EG13: -0.11467646 | EH13: 0.027773598 | EI13: -0.49952429 | EJ13: -0.063207559 | EK13: -0.020549934 | EL13: 0.5513367 | EM13: -0.30860041 | EN13: -0.48882526 | EO13: -0.40122641 | EP13: -0.12780143 | EQ13: -0.078124048 | ER13: -0.032633284 | ES13: -0.14519587 | ET13: 0.55654122 | EU13: 0.57792304 | EV13: -0.16738266 | EW13: 0.15902448 | EX13: 0.037719301 | EY13: -0.075586027 | EZ13: 0.62516101 | FA13: 0.039238723 | FB13: -0.15498563 | FC13: 0.24654324 | FD13: -0.16000059 | FE13: 0.1274148 | FF13: 0.15471354 | FG13: 0.38350406 | FH13: 0.18469547 | FI13: -0.11620783 | FJ13: 0.60679985 | FK13: 0.1960233 | FL13: 0.13546755 | FM13: -0.2361899 | FN13: -0.60125649 | FO13: -0.41092826 | FP13: 0.35751836 | FQ13: 0.1603874 | FR13: 0.73024816 | FS13: 0.21674412 | FT13: 0.024103105 | FU13: 0.13647268 | FV13: 0.017888769 | FW13: 0.17202945 | FX13: -0.5538336 | FY13: -0.3417528 | FZ13: -0.46799521 | GA13: 0.087476886 | GB13: 0.6443035 | GC13: -0.37300812 | GD13: -0.40004973 | GE13: -0.550017 | GF13: -0.2991545 | GG13: -0.25118512 | GH13: -0.35370952 | GI13: -0.36215558 | GJ13: -0.13303769 | GK13: 0.11217345 | GL13: 0.13849912 | GM13: -0.14509052 | GN13: -0.39793243 | GO13: -0.31291581 | GP13: -0.1966656 | GQ13: 0.0034316518 | GR13: -0.14831935 | GS13: -0.091839766 | GT13: -0.34218093 | GU13: -0.22832596 | GV13: -0.026458556 | GW13: -0.050200968 | GX13: 0.34072339 | GY13: 0.076038957 | GZ13: -0.063349557 | HA13: -0.17452765 | HB13: -0.015049008 | HC13: 0.59483651
... A216: epc265 | B216: =ABS(DC216) -> 0.17689293 | C216: =ABS(DD216) -> 0.34302171 | D216: =ABS(DE216) -> 0.054250116 | E216: =ABS(DF216) -> 0.51469216 | F216: =ABS(DG216) -> 0.41906453 | G216: =ABS(DH216) -> 0.34588552 | H216: =ABS(DI216) -> 0.62085577 | I216: =ABS(DJ216) -> 0.39929502 | ... DB216: =ABS(HC216) -> 0.90101144 | DC216: 0.17689293 | DD216: 0.34302171 | DE216: 0.054250116 | DF216: 0.51469216 | DG216: 0.41906453 | DH216: 0.34588552 | DI216: 0.62085577 | DJ216: 0.39929502 | DK216: 0.093573947 | DL216: 0.17978751 | DM216: 0.37733554 | DN216: 0.28709475 | DO216: 0.2409651 | DP216: 0.31825976 | DQ216: 0.24929782 | DR216: 0.0047597937 | DS216: 0.2440157 | DT216: 0.18608352 | DU216: 0.28910375 | DV216: -0.045992556 | DW216: 0.47876414 | DX216: 0.42452124 | DY216: 0.14402417 | DZ216: 0.016852307 | EA216: 0.42008986 | EB216: 0.16231942 | EC216: 0.31734255 | ED216: 0.21145457 | EE216: 0.4281926 | EF216: -0.13065771 | EG216: 0.10837464 | EH216: 0.64302846 | EI216: -0.070582678 | EJ216: 0.17604335 | EK216: 0.064165388 | EL216: 0.68398187 | EM216: -0.34872234 | EN216: -0.15447859 | EO216: 0.059727021 | EP216: 0.023500018 | EQ216: -0.41743884 | ER216: -0.45351572 | ES216: 0.097118337 | ET216: 0.022770477 | EU216: 0.24279726 | EV216: -0.52812446 | EW216: 0.058188032 | EX216: -0.15285428 | EY216: -0.17066355 | EZ216: -0.40155931 | FA216: -0.11225716 | FB216: 0.12316042 | FC216: 0.17512217 | FD216: 0.083563927 | FE216: 0.6296029 | FF216: 0.20497535 | FG216: 0.11843026 | FH216: -0.067467309 | FI216: -0.055213537 | FJ216: 0.54817549 | FK216: -0.16077718 | FL216: -0.07706764 | FM216: -0.070692129 | FN216: -0.34727025 | FO216: -0.17709058 | FP216: -0.25642847 | FQ216: 0.18308036 | FR216: 0.29604314 | FS216: 0.03737419 | FT216: 0.24803308 | FU216: 0.46593471 | FV216: -0.079759403 | FW216: 0.061890242 | FX216: 0.017052608 | FY216: -0.17689732 | FZ216: -0.18058184 | GA216: -0.1294139 | GB216: 1.0370083 | GC216: -0.39179274 | GD216: 0.19363772 | GE216: 0.076698358 | GF216: -0.22083298 | GG216: -0.14875301 | GH216: -0.04961663 | GI216: 0.18585328 | GJ216: -0.13093063 | GK216: -0.38605841 | GL216: 0.32986809 | GM216: 0.29756503 | GN216: 0.13999429 | GO216: 0.090439206 | GP216: -0.35053499 | GQ216: 0.2844517 | GR216: -0.0042112111 | GS216: -0.038239311 | GT216: -0.15332648 | GU216: -0.16320159 | GV216: 0.14955683 | GW216: -0.091903406 | GX216: -0.25892364 | GY216: 0.46305232 | GZ216: 0.40244383 | HA216: 0.071218384 | HB216: 0.17760569 | HC216: 0.90101144

Sheet outcomeanddemographics
A1: SubjectID | B1: BinaryOutcome | C1: demographic1 | D1: demographic2 | E1: demographic3 | F1: demographic4 | G1: demographic5 | H1: BPRSBaseline_Rescaled | I1: Education | J1: Parental Education | L1: Feature7 (optional)
A2: SID | B2: Imp20PercentBPRS | C2: Age | D2: handedness | E2: sex | F2: PrimaryEthnicity | G2: PrimaryRace | I2: Education | J2: Parental Education | L2: BPRS_Baseline
A3: epp270 | B3: 1 | C3: 13 | D3: 1 | E3: 1 | F3: 0 | G3: 4 | H3: =VLOOKUP(A3,Sheet2!A:B,2,0) -> 18 | I3: 7 | J3: 19 | L3: 42
A4: epp271 | B4: 1 | C4: 25 | D4: 1 | E4: 1 | F4: 1 | G4: 4 | H4: =VLOOKUP(A4,Sheet2!A:B,2,0) -> 29 | I4: =VLOOKUP(A4,Sheet1!A:C,3,0) -> 12 | J4: =VLOOKUP(A4,Sheet1!A:F,6,0) -> 15 | L4: 53
A5: epp274 | B5: 1 | C5: 19 | D5: 1 | E5: 1 | F5: 0 | G5: 4 | H5: =VLOOKUP(A5,Sheet2!A:B,2,0) -> 23 | I5: =VLOOKUP(A5,Sheet1!A:C,3,0) -> 12 | J5: =VLOOKUP(A5,Sheet1!A:F,6,0) -> 16 | L5: 47
A6: epp278 | B6: 0 | C6: 20 | D6: 1 | E6: 1 | F6: 0 | G6: 4 | H6: =VLOOKUP(A6,Sheet2!A:B,2,0) -> 20 | I6: =VLOOKUP(A6,Sheet1!A:C,3,0) -> 13 | J6: =VLOOKUP(A6,Sheet1!A:F,6,0) -> 16.5 | L6: 44
A7: epp309 | B7: 0 | C7: 22 | D7: 1 | E7: 1 | F7: 0 | G7: 4 | H7: =VLOOKUP(A7,Sheet2!A:B,2,0) -> 15 | I7: =VLOOKUP(A7,Sheet1!A:C,3,0) -> 14 | J7: =VLOOKUP(A7,Sheet1!A:F,6,0) -> 12 | L7: 39
A8: epp314 | B8: 1 | C8: 21 | D8: 1 | E8: 2 | F8: 0 | G8: 4 | H8: =VLOOKUP(A8,Sheet2!A:B,2,0) -> 21 | I8: =VLOOKUP(A8,Sheet1!A:C,3,0) -> 14 | J8: =VLOOKUP(A8,Sheet1!A:F,6,0) -> 18 | L8: 45
A9: epp321 | B9: 1 | C9: 15 | D9: 2 | E9: 1 | F9: 0 | G9: 4 | H9: =VLOOKUP(A9,Sheet2!A:B,2,0) -> 21 | I9: =VLOOKUP(A9,Sheet1!A:C,3,0) -> 9 | J9: =VLOOKUP(A9,Sheet1!A:F,6,0) -> 16 | L9: 45
A10: epp322 | B10: 1 | C10: 20 | D10: 1 | E10: 2 | F10: 0 | G10: 2 | H10: =VLOOKUP(A10,Sheet2!A:B,2,0) -> 19 | I10: =VLOOKUP(A10,Sheet1!A:C,3,0) -> 13 | J10: =VLOOKUP(A10,Sheet1!A:F,6,0) -> 4 | L10: 43
A11: epp330 | B11: 0 | C11: 18 | D11: 1 | E11: 2 | F11: 0 | G11: 4 | H11: =VLOOKUP(A11,Sheet2!A:B,2,0) -> 24 | I11: =VLOOKUP(A11,Sheet1!A:C,3,0) -> 12 | J11: =VLOOKUP(A11,Sheet1!A:F,6,0) -> 15 | L11: 48
A12: epp337 | B12: 0 | C12: 19 | D12: 1 | E12: 2 | F12: 0 | G12: 4 | H12: =VLOOKUP(A12,Sheet2!A:B,2,0) -> 6 | I12: =VLOOKUP(A12,Sheet1!A:C,3,0) -> 14 | J12: =VLOOKUP(A12,Sheet1!A:F,6,0) -> 16 | L12: 30
A13: epp339 | B13: 0 | C13: 16 | D13: 1 | E13: 1 | F13: 0 | G13: 4 | H13: =VLOOKUP(A13,Sheet2!A:B,2,0) -> 40 | I13: =VLOOKUP(A13,Sheet1!A:C,3,0) -> 10 | J13: =VLOOKUP(A13,Sheet1!A:F,6,0) -> 14 | L13: 64
A14: epp344 | B14: 1 | C14: 19 | D14: 1 | E14: 1 | F14: 0 | G14: 1 | H14: =VLOOKUP(A14,Sheet2!A:B,2,0) -> 19 | I14: =VLOOKUP(A14,Sheet1!A:C,3,0) -> 12 | J14: =VLOOKUP(A14,Sheet1!A:F,6,0) -> 14 | L14: 43
A15: epp348 | B15: 0 | C15: 25 | D15: 1 | E15: 2 | F15: 1 | G15: 4 | H15: =VLOOKUP(A15,Sheet2!A:B,2,0) -> 21 | I15: =VLOOKUP(A15,Sheet1!A:C,3,0) -> 13 | J15: =VLOOKUP(A15,Sheet1!A:F,6,0) -> 11.5 | L15: 45
... A22: epp381 | B22: 0 | C22: 19 | D22: 1 | E22: 1 | F22: 0 | G22: 2 | H22: =VLOOKUP(A22,Sheet2!A:B,2,0) -> 17 | I22: =VLOOKUP(A22,Sheet1!A:C,3,0) -> 12 | J22: =VLOOKUP(A22,Sheet1!A:F,6,0) -> 15 | L22: 41
A23: epp388 | B23: 0 | C23: 16 | D23: 1 | E23: 1 | F23: 1 | G23: 4 | H23: =VLOOKUP(A23,Sheet2!A:B,2,0) -> 9 | I23: =VLOOKUP(A23,Sheet1!A:C,3,0) -> 11 | L23: 33
A24: epp394 | B24: 1 | C24: 20 | D24: 1 | E24: 1 | F24: 0 | G24: 4 | H24: =VLOOKUP(A24,Sheet2!A:B,2,0) -> 12 | I24: =VLOOKUP(A24,Sheet1!A:C,3,0) -> 14 | J24: =VLOOKUP(A24,Sheet1!A:F,6,0) -> 18 | L24: 36
A25: epp421 | B25: 1 | C25: 20 | D25: 2 | E25: 1 | F25: 0 | G25: 4 | H25: =VLOOKUP(A25,Sheet2!A:B,2,0) -> 15 | I25: =VLOOKUP(A25,Sheet1!A:C,3,0) -> 14 | J25: =VLOOKUP(A25,Sheet1!A:F,6,0) -> 16 | L25: 39
A26: epp434 | B26: 0 | C26: 22 | D26: 2 | E26: 2 | F26: 0 | G26: 1 | H26: =VLOOKUP(A26,Sheet2!A:B,2,0) -> 12 | I26: =VLOOKUP(A26,Sheet1!A:C,3,0) -> 14 | J26: =VLOOKUP(A26,Sheet1!A:F,6,0) -> 12.5 | L26: 36
A27: epp440 | B27: 1 | C27: 20 | D27: 1 | E27: 1 | F27: 0 | G27: 4 | H27: =VLOOKUP(A27,Sheet2!A:B,2,0) -> 18 | I27: =VLOOKUP(A27,Sheet1!A:C,3,0) -> 13 | J27: =VLOOKUP(A27,Sheet1!A:F,6,0) -> 12.5 | L27: 42
A28: epp442 | B28: 0 | C28: 20 | D28: 1 | E28: 2 | F28: 1 | G28: 6 | H28: =VLOOKUP(A28,Sheet2!A:B,2,0) -> 18 | I28: =VLOOKUP(A28,Sheet1!A:C,3,0) -> 14 | J28: =VLOOKUP(A28,Sheet1!A:F,6,0) -> 13 | L28: 42
A29: epp454 | B29: 1 | C29: 25 | D29: 1 | E29: 1 | F29: 1 | G29: 4 | H29: =VLOOKUP(A29,Sheet2!A:B,2,0) -> 23 | I29: =VLOOKUP(A29,Sheet1!A:C,3,0) -> 12 | J29: =VLOOKUP(A29,Sheet1!A:F,6,0) -> 10 | L29: 47
A30: epp469 | B30: 1 | C30: 15 | D30: 0 | E30: 2 | F30: 0 | G30: 1 | H30: =VLOOKUP(A30,Sheet2!A:B,2,0) -> 32 | I30: =VLOOKUP(A30,Sheet1!A:C,3,0) -> 9 | J30: =VLOOKUP(A30,Sheet1!A:F,6,0) -> 12 | L30: 56
A31: epp477 | B31: 0 | C31: 15 | D31: 1 | E31: 1 | F31: 1 | G31: 6 | H31: =VLOOKUP(A31,Sheet2!A:B,2,0) -> 1 | I31: =VLOOKUP(A31,Sheet1!A:C,3,0) -> 10 | L31: 25
A32: epp482 | B32: 0 | C32: 20 | D32: 1 | E32: 1 | F32: 1 | G32: 4 | H32: =VLOOKUP(A32,Sheet2!A:B,2,0) -> 7 | I32: =VLOOKUP(A32,Sheet1!A:C,3,0) -> 10 | J32: =VLOOKUP(A32,Sheet1!A:F,6,0) -> 8 | L32: 31
A33: epp483 | B33: 0 | C33: 19 | D33: 1 | E33: 2 | F33: 0 | G33: 2 | H33: =VLOOKUP(A33,Sheet2!A:B,2,0) -> 0 | I33: =VLOOKUP(A33,Sheet1!A:C,3,0) -> 12 | J33: =VLOOKUP(A33,Sheet1!A:F,6,0) -> 19 | L33: 24
A34: epp484 | B34: 1 | C34: 18 | D34: 1 | E34: 1 | F34: 1 | G34: 4 | H34: =VLOOKUP(A34,Sheet2!A:B,2,0) -> 35 | I34: =VLOOKUP(A34,Sheet1!A:C,3,0) -> 12 | J34: =VLOOKUP(A34,Sheet1!A:F,6,0) -> 9 | L34: 59
A35: epp506 | B35: 0 | C35: 15 | D35: 1 | E35: 2 | F35: 1 | G35: 4 | H35: =VLOOKUP(A35,Sheet2!A:B,2,0) -> 4 | I35: =VLOOKUP(A35,Sheet1!A:C,3,0) -> 8 | J35: =VLOOKUP(A35,Sheet1!A:F,6,0) -> 11 | L35: 28
A36: epp508 | B36: 1 | C36: 24 | D36: 1 | E36: 2 | F36: 0 | G36: 4 | H36: =VLOOKUP(A36,Sheet2!A:B,2,0) -> 16 | I36: =VLOOKUP(A36,Sheet1!A:C,3,0) -> 13 | J36: =VLOOKUP(A36,Sheet1!A:F,6,0) -> 12 | L36: 40
A37: epp511 | B37: 0 | C37: 18 | D37: 1 | E37: 1 | F37: 1 | G37: 5 | H37: =VLOOKUP(A37,Sheet2!A:B,2,0) -> 15 | I37: =VLOOKUP(A37,Sheet1!A:C,3,0) -> 10 | J37: =VLOOKUP(A37,Sheet1!A:F,6,0) -> 13 | L37: 39
A38: epp516 | B38: 1 | C38: 18 | D38: 2 | E38: 1 | F38: 1 | G38: 4 | H38: =VLOOKUP(A38,Sheet2!A:B,2,0) -> 11 | I38: =VLOOKUP(A38,Sheet1!A:C,3,0) -> 13 | J38: =VLOOKUP(A38,Sheet1!A:F,6,0) -> 15 | L38: 35
A39: epp528 | B39: 1 | C39: 16 | D39: 1 | E39: 1 | F39: 0 | G39: 4 | H39: =VLOOKUP(A39,Sheet2!A:B,2,0) -> 14 | I39: =VLOOKUP(A39,Sheet1!A:C,3,0) -> 10 | J39: =VLOOKUP(A39,Sheet1!A:F,6,0) -> 17 | L39: 38
A40: epp549 | B40: 1 | C40: 17 | D40: 1 | E40: 1 | F40: 0 | G40: 1 | H40: =VLOOKUP(A40,Sheet2!A:B,2,0) -> 18 | I40: =VLOOKUP(A40,Sheet1!A:C,3,0) -> 11 | L40: 42
A41: epp551 | B41: 0 | C41: 19 | D41: 1 | E41: 2 | F41: 0 | G41: 4 | H41: =VLOOKUP(A41,Sheet2!A:B,2,0) -> 10 | I41: =VLOOKUP(A41,Sheet1!A:C,3,0) -> 13 | J41: =VLOOKUP(A41,Sheet1!A:F,6,0) -> 16 | L41: 34
A42: epp557 | B42: 0 | C42: 16 | D42: 1 | E42: 2 | F42: 0 | G42: 4 | H42: =VLOOKUP(A42,Sheet2!A:B,2,0) -> 4 | I42: =VLOOKUP(A42,Sheet1!A:C,3,0) -> 9 | J42: =VLOOKUP(A42,Sheet1!A:F,6,0) -> 18 | L42: 28
A43: epp598 | B43: 1 | C43: 15 | D43: 1 | E43: 2 | F43: 0 | G43: 1 | H43: =VLOOKUP(A43,Sheet2!A:B,2,0) -> 30 | I43: =VLOOKUP(A43,Sheet1!A:C,3,0) -> 10 | J43: =VLOOKUP(A43,Sheet1!A:F,6,0) -> 16 | L43: 54
A44: epp601 | B44: 0 | C44: 22 | D44: 1 | E44: 1 | F44: 0 | G44: 2 | H44: =VLOOKUP(A44,Sheet2!A:B,2,0) -> 21 | I44: =VLOOKUP(A44,Sheet1!A:C,3,0) -> 16 | J44: =VLOOKUP(A44,Sheet1!A:F,6,0) -> 17 | L44: 45
A45: epp603 | B45: 0 | C45: 14 | D45: 1 | E45: 2 | F45: 0 | G45: 4 | H45: =VLOOKUP(A45,Sheet2!A:B,2,0) -> 16 | I45: =VLOOKUP(A45,Sheet1!A:C,3,0) -> 9 | J45: =VLOOKUP(A45,Sheet1!A:F,6,0) -> 18 | L45: 40
A46: epp611 | B46: 0 | C46: 23 | D46: 1 | E46: 2 | F46: 1 | G46: 4 | H46: =VLOOKUP(A46,Sheet2!A:B,2,0) -> 16 | I46: =VLOOKUP(A46,Sheet1!A:C,3,0) -> 15 | J46: =VLOOKUP(A46,Sheet1!A:F,6,0) -> 16.5 | L46: 40
...

Sheet Sheet1
A1: pt_info_ep_id | B1: WASI2IQ | C1: demo_subject_educ | D1: demo_mom_educ | E1: demo_dad_educ | F1: ParentalEducation
A2: epc01
A3: epc02
A4: epc03 | B4: 125
A5: epc04 | B5: 114
A6: epc05 | B6: 124
A7: epc06 | B7: 85
A8: epc07 | B8: 122
A9: epc08 | B9: 118
A10: epc09 | B10: 117
A11: epc10
A12: epc100 | B12: 123
A13: epc101
A14: epc102 | B14: 142
A15: epc103 | B15: 115
A16: epc104
A17: epc105 | B17: 113
A18: epc106 | B18: 107
A19: epc107 | B19: 98
A20: epc108 | B20: 118
A21: epc109 | B21: 115
A22: epc11 | B22: 117
A23: epc110
A24: epc111 | B24: 119
A25: epc112 | B25: 102
A26: epc113 | B26: 121
A27: epc114 | B27: 135
A28: epc115 | B28: 115
A29: epc116 | B29: 102
A30: epc117
A31: epc118 | B31: 118
A32: epc119 | B32: 110
A33: epc12
A34: epc120 | B34: 117
A35: epc121 | B35: 103
A36: epc122 | B36: 91
A37: epc123 | B37: 105
A38: epc124
A39: epc125
A40: epc126 | B40: 121
...

Sheet Sheet2
A1: SID | B1: BPRS_Baseline_Rescaled
A2: epc138
A3: epc139
A4: epc140
A5: epc141
A6: epc142
A7: epc143
A8: epc144
A9: epc145
A10: epc146
A11: epc147
A12: epc149
A13: epc150
... A88: epc265
A89: epp270 | B89: 18
A90: epp271 | B90: 29
A91: epp274 | B91: 23
A92: epp278 | B92: 20
A93: epp309 | B93: 15
A94: epp310 | B94: 13
A95: epp312 | B95: 2
A96: epp314 | B96: 21
A97: epp319 | B97: 22
A98: epp320 | B98: 9
A99: epp321 | B99: 21
A100: epp322 | B100: 19
... A122: epp369 | B122: 8
A123: epp370
A124: epp371 | B124: 33
A125: epp372 | B125: 14
A126: epp374 | B126: 6
A127: epp377 | B127: 48
A128: epp379 | B128: 21
A129: epp381 | B129: 17
A130: epp383 | B130: 1
A131: epp385 | B131: 7
A132: epp388 | B132: 9
A133: epp389 | B133: 14
A134: epp393 | B134: 18
A135: epp394 | B135: 12
...
